Wed Jan 20 02:24:16 PST 2016
Wed Jan 20 02:30:39 PST 2016
/usr/lib/python3/dist-packages/scipy/stats/distributions.py:1334: RuntimeWarning: invalid value encountered in double_scalars
  x = (x-loc)*1.0/scale
Error: cannot insert artist_genre into db
'electro.soul'
'electro.soul'
Error: cannot insert artist_genre into db
'sample'
'sample'
Error: cannot insert artist_genre into db
'parody'
'parody'
Error: cannot insert artist_genre into db
'sample'
'sample'
Error: cannot insert artist_genre into db
'drumandbass'
'drumandbass'
Error: cannot insert album_genre into db
'electronic'
'electronic'
Error: cannot insert artist_genre into db
'contemporary'
'contemporary'
Error: cannot insert artist_genre into db
'psychedelic.trance'
'psychedelic.trance'
Error: cannot insert album_genre into db
'tropicalia'
'tropicalia'
Error: cannot insert artist_genre into db
'tropicalia'
'tropicalia'
Error: cannot insert album_genre into db
'romantic'
'romantic'
Error: cannot insert artist_genre into db
'psychedelic.trance'
'psychedelic.trance'
Error: cannot insert album_genre into db
'disco'
'disco'
Error: cannot insert artist_genre into db
'flute'
'flute'
Error: cannot insert album_genre into db
'alternative.pop'
'alternative.pop'
Error: cannot insert artist_genre into db
'synthwave'
'synthwave'
Response status is not successful, it is failure

list index out of range
Response status is not successful, it is failure

list index out of range
Traceback (most recent call last):
  File "downloader/everythingLookup.py", line 331, in <module>
    main()
  File "downloader/everythingLookup.py", line 326, in main
    lookupAll(sys.argv[1],conf,fields)
  File "downloader/everythingLookup.py", line 308, in lookupAll
    lookupKUPS(conf,fields)
  File "downloader/everythingLookup.py", line 271, in lookupKUPS
    song=track["SongName"])
  File "packages/libzarv.py", line 228, in getAlbumArtistNames
    "groupName":x['title']}), 
  File "packages/libzarv.py", line 281, in getSongs
    limit=1)['release-list']
  File "/usr/local/lib/python3.4/dist-packages/musicbrainzngs/musicbrainz.py", line 868, in search_releases
    return _do_mb_search('release', query, fields, limit, offset, strict)
  File "/usr/local/lib/python3.4/dist-packages/musicbrainzngs/musicbrainz.py", line 728, in _do_mb_search
    return _do_mb_query(entity, '', [], params)
  File "/usr/local/lib/python3.4/dist-packages/musicbrainzngs/musicbrainz.py", line 670, in _do_mb_query
    return _mb_request(path, 'GET', auth_required, args=args)
  File "/usr/local/lib/python3.4/dist-packages/musicbrainzngs/musicbrainz.py", line 374, in __call__
    return self.fun(*args, **kwargs)
  File "/usr/local/lib/python3.4/dist-packages/musicbrainzngs/musicbrainz.py", line 635, in _mb_request
    resp = _safe_read(opener, req, body)
  File "/usr/local/lib/python3.4/dist-packages/musicbrainzngs/musicbrainz.py", line 494, in _safe_read
    raise NetworkError("retried %i times" % max_retries, last_exc)
musicbrainzngs.musicbrainz.NetworkError: retried 8 times, caused by: timed out
Wed Jan 20 07:50:54 PST 2016
Traceback (most recent call last):
  File "downloader/everythingLookup.py", line 331, in <module>
    main()
  File "downloader/everythingLookup.py", line 326, in main
    lookupAll(sys.argv[1],conf,fields)
  File "downloader/everythingLookup.py", line 308, in lookupAll
    lookupKUPS(conf,fields)
  File "downloader/everythingLookup.py", line 271, in lookupKUPS
    song=track["SongName"])
  File "packages/libzarv.py", line 174, in getAlbumArtistNames
    mbArtists = mb.search_artists(query=artist,limit=10)['artist-list']
  File "/usr/local/lib/python3.4/dist-packages/musicbrainzngs/musicbrainz.py", line 846, in search_artists
    return _do_mb_search('artist', query, fields, limit, offset, strict)
  File "/usr/local/lib/python3.4/dist-packages/musicbrainzngs/musicbrainz.py", line 728, in _do_mb_search
    return _do_mb_query(entity, '', [], params)
  File "/usr/local/lib/python3.4/dist-packages/musicbrainzngs/musicbrainz.py", line 670, in _do_mb_query
    return _mb_request(path, 'GET', auth_required, args=args)
  File "/usr/local/lib/python3.4/dist-packages/musicbrainzngs/musicbrainz.py", line 374, in __call__
    return self.fun(*args, **kwargs)
  File "/usr/local/lib/python3.4/dist-packages/musicbrainzngs/musicbrainz.py", line 635, in _mb_request
    resp = _safe_read(opener, req, body)
  File "/usr/local/lib/python3.4/dist-packages/musicbrainzngs/musicbrainz.py", line 494, in _safe_read
    raise NetworkError("retried %i times" % max_retries, last_exc)
musicbrainzngs.musicbrainz.NetworkError: retried 8 times, caused by: HTTP Error 503: Service Unavailable
Wed Jan 20 07:52:52 PST 2016
Traceback (most recent call last):
  File "downloader/everythingLookup.py", line 331, in <module>
    main()
  File "downloader/everythingLookup.py", line 326, in main
    lookupAll(sys.argv[1],conf,fields)
  File "downloader/everythingLookup.py", line 308, in lookupAll
    lookupKUPS(conf,fields)
  File "downloader/everythingLookup.py", line 271, in lookupKUPS
    song=track["SongName"])
  File "packages/libzarv.py", line 174, in getAlbumArtistNames
    mbArtists = mb.search_artists(query=artist,limit=10)['artist-list']
  File "/usr/local/lib/python3.4/dist-packages/musicbrainzngs/musicbrainz.py", line 846, in search_artists
    return _do_mb_search('artist', query, fields, limit, offset, strict)
  File "/usr/local/lib/python3.4/dist-packages/musicbrainzngs/musicbrainz.py", line 728, in _do_mb_search
    return _do_mb_query(entity, '', [], params)
  File "/usr/local/lib/python3.4/dist-packages/musicbrainzngs/musicbrainz.py", line 670, in _do_mb_query
    return _mb_request(path, 'GET', auth_required, args=args)
  File "/usr/local/lib/python3.4/dist-packages/musicbrainzngs/musicbrainz.py", line 374, in __call__
    return self.fun(*args, **kwargs)
  File "/usr/local/lib/python3.4/dist-packages/musicbrainzngs/musicbrainz.py", line 635, in _mb_request
    resp = _safe_read(opener, req, body)
  File "/usr/local/lib/python3.4/dist-packages/musicbrainzngs/musicbrainz.py", line 494, in _safe_read
    raise NetworkError("retried %i times" % max_retries, last_exc)
musicbrainzngs.musicbrainz.NetworkError: retried 8 times, caused by: HTTP Error 503: Service Unavailable
Wed Jan 20 07:54:21 PST 2016
/usr/lib/python3/dist-packages/scipy/stats/distributions.py:1334: RuntimeWarning: invalid value encountered in double_scalars
  x = (x-loc)*1.0/scale
Traceback (most recent call last):
  File "downloader/everythingLookup.py", line 331, in <module>
    main()
  File "downloader/everythingLookup.py", line 326, in main
    lookupAll(sys.argv[1],conf,fields)
  File "downloader/everythingLookup.py", line 308, in lookupAll
    lookupKUPS(conf,fields)
  File "downloader/everythingLookup.py", line 271, in lookupKUPS
    song=track["SongName"])
  File "packages/libzarv.py", line 174, in getAlbumArtistNames
    mbArtists = mb.search_artists(query=artist,limit=10)['artist-list']
  File "/usr/local/lib/python3.4/dist-packages/musicbrainzngs/musicbrainz.py", line 846, in search_artists
    return _do_mb_search('artist', query, fields, limit, offset, strict)
  File "/usr/local/lib/python3.4/dist-packages/musicbrainzngs/musicbrainz.py", line 728, in _do_mb_search
    return _do_mb_query(entity, '', [], params)
  File "/usr/local/lib/python3.4/dist-packages/musicbrainzngs/musicbrainz.py", line 670, in _do_mb_query
    return _mb_request(path, 'GET', auth_required, args=args)
  File "/usr/local/lib/python3.4/dist-packages/musicbrainzngs/musicbrainz.py", line 374, in __call__
    return self.fun(*args, **kwargs)
  File "/usr/local/lib/python3.4/dist-packages/musicbrainzngs/musicbrainz.py", line 635, in _mb_request
    resp = _safe_read(opener, req, body)
  File "/usr/local/lib/python3.4/dist-packages/musicbrainzngs/musicbrainz.py", line 494, in _safe_read
    raise NetworkError("retried %i times" % max_retries, last_exc)
musicbrainzngs.musicbrainz.NetworkError: retried 8 times, caused by: timed out
Wed Jan 20 08:00:09 PST 2016
Traceback (most recent call last):
  File "downloader/everythingLookup.py", line 331, in <module>
    main()
  File "downloader/everythingLookup.py", line 326, in main
    lookupAll(sys.argv[1],conf,fields)
  File "downloader/everythingLookup.py", line 308, in lookupAll
    lookupKUPS(conf,fields)
  File "downloader/everythingLookup.py", line 271, in lookupKUPS
    song=track["SongName"])
  File "packages/libzarv.py", line 174, in getAlbumArtistNames
    mbArtists = mb.search_artists(query=artist,limit=10)['artist-list']
  File "/usr/local/lib/python3.4/dist-packages/musicbrainzngs/musicbrainz.py", line 846, in search_artists
    return _do_mb_search('artist', query, fields, limit, offset, strict)
  File "/usr/local/lib/python3.4/dist-packages/musicbrainzngs/musicbrainz.py", line 728, in _do_mb_search
    return _do_mb_query(entity, '', [], params)
  File "/usr/local/lib/python3.4/dist-packages/musicbrainzngs/musicbrainz.py", line 670, in _do_mb_query
    return _mb_request(path, 'GET', auth_required, args=args)
  File "/usr/local/lib/python3.4/dist-packages/musicbrainzngs/musicbrainz.py", line 374, in __call__
    return self.fun(*args, **kwargs)
  File "/usr/local/lib/python3.4/dist-packages/musicbrainzngs/musicbrainz.py", line 635, in _mb_request
    resp = _safe_read(opener, req, body)
  File "/usr/local/lib/python3.4/dist-packages/musicbrainzngs/musicbrainz.py", line 494, in _safe_read
    raise NetworkError("retried %i times" % max_retries, last_exc)
musicbrainzngs.musicbrainz.NetworkError: retried 8 times, caused by: timed out
Wed Jan 20 08:02:17 PST 2016
Traceback (most recent call last):
  File "downloader/everythingLookup.py", line 331, in <module>
    main()
  File "downloader/everythingLookup.py", line 326, in main
    lookupAll(sys.argv[1],conf,fields)
  File "downloader/everythingLookup.py", line 308, in lookupAll
    lookupKUPS(conf,fields)
  File "downloader/everythingLookup.py", line 271, in lookupKUPS
    song=track["SongName"])
  File "packages/libzarv.py", line 174, in getAlbumArtistNames
    mbArtists = mb.search_artists(query=artist,limit=10)['artist-list']
  File "/usr/local/lib/python3.4/dist-packages/musicbrainzngs/musicbrainz.py", line 846, in search_artists
    return _do_mb_search('artist', query, fields, limit, offset, strict)
  File "/usr/local/lib/python3.4/dist-packages/musicbrainzngs/musicbrainz.py", line 728, in _do_mb_search
    return _do_mb_query(entity, '', [], params)
  File "/usr/local/lib/python3.4/dist-packages/musicbrainzngs/musicbrainz.py", line 670, in _do_mb_query
    return _mb_request(path, 'GET', auth_required, args=args)
  File "/usr/local/lib/python3.4/dist-packages/musicbrainzngs/musicbrainz.py", line 374, in __call__
    return self.fun(*args, **kwargs)
  File "/usr/local/lib/python3.4/dist-packages/musicbrainzngs/musicbrainz.py", line 635, in _mb_request
    resp = _safe_read(opener, req, body)
  File "/usr/local/lib/python3.4/dist-packages/musicbrainzngs/musicbrainz.py", line 494, in _safe_read
    raise NetworkError("retried %i times" % max_retries, last_exc)
musicbrainzngs.musicbrainz.NetworkError: retried 8 times, caused by: timed out
Wed Jan 20 08:04:25 PST 2016
Traceback (most recent call last):
  File "downloader/everythingLookup.py", line 331, in <module>
    main()
  File "downloader/everythingLookup.py", line 326, in main
    lookupAll(sys.argv[1],conf,fields)
  File "downloader/everythingLookup.py", line 308, in lookupAll
    lookupKUPS(conf,fields)
  File "downloader/everythingLookup.py", line 271, in lookupKUPS
    song=track["SongName"])
  File "packages/libzarv.py", line 174, in getAlbumArtistNames
    mbArtists = mb.search_artists(query=artist,limit=10)['artist-list']
  File "/usr/local/lib/python3.4/dist-packages/musicbrainzngs/musicbrainz.py", line 846, in search_artists
    return _do_mb_search('artist', query, fields, limit, offset, strict)
  File "/usr/local/lib/python3.4/dist-packages/musicbrainzngs/musicbrainz.py", line 728, in _do_mb_search
    return _do_mb_query(entity, '', [], params)
  File "/usr/local/lib/python3.4/dist-packages/musicbrainzngs/musicbrainz.py", line 670, in _do_mb_query
    return _mb_request(path, 'GET', auth_required, args=args)
  File "/usr/local/lib/python3.4/dist-packages/musicbrainzngs/musicbrainz.py", line 374, in __call__
    return self.fun(*args, **kwargs)
  File "/usr/local/lib/python3.4/dist-packages/musicbrainzngs/musicbrainz.py", line 635, in _mb_request
    resp = _safe_read(opener, req, body)
  File "/usr/local/lib/python3.4/dist-packages/musicbrainzngs/musicbrainz.py", line 494, in _safe_read
    raise NetworkError("retried %i times" % max_retries, last_exc)
musicbrainzngs.musicbrainz.NetworkError: retried 8 times, caused by: timed out
Wed Jan 20 08:06:34 PST 2016
Traceback (most recent call last):
  File "downloader/everythingLookup.py", line 331, in <module>
    main()
  File "downloader/everythingLookup.py", line 326, in main
    lookupAll(sys.argv[1],conf,fields)
  File "downloader/everythingLookup.py", line 308, in lookupAll
    lookupKUPS(conf,fields)
  File "downloader/everythingLookup.py", line 271, in lookupKUPS
    song=track["SongName"])
  File "packages/libzarv.py", line 174, in getAlbumArtistNames
    mbArtists = mb.search_artists(query=artist,limit=10)['artist-list']
  File "/usr/local/lib/python3.4/dist-packages/musicbrainzngs/musicbrainz.py", line 846, in search_artists
    return _do_mb_search('artist', query, fields, limit, offset, strict)
  File "/usr/local/lib/python3.4/dist-packages/musicbrainzngs/musicbrainz.py", line 728, in _do_mb_search
    return _do_mb_query(entity, '', [], params)
  File "/usr/local/lib/python3.4/dist-packages/musicbrainzngs/musicbrainz.py", line 670, in _do_mb_query
    return _mb_request(path, 'GET', auth_required, args=args)
  File "/usr/local/lib/python3.4/dist-packages/musicbrainzngs/musicbrainz.py", line 374, in __call__
    return self.fun(*args, **kwargs)
  File "/usr/local/lib/python3.4/dist-packages/musicbrainzngs/musicbrainz.py", line 635, in _mb_request
    resp = _safe_read(opener, req, body)
  File "/usr/local/lib/python3.4/dist-packages/musicbrainzngs/musicbrainz.py", line 494, in _safe_read
    raise NetworkError("retried %i times" % max_retries, last_exc)
musicbrainzngs.musicbrainz.NetworkError: retried 8 times, caused by: timed out
Wed Jan 20 08:08:42 PST 2016
Traceback (most recent call last):
  File "downloader/everythingLookup.py", line 331, in <module>
    main()
  File "downloader/everythingLookup.py", line 326, in main
    lookupAll(sys.argv[1],conf,fields)
  File "downloader/everythingLookup.py", line 308, in lookupAll
    lookupKUPS(conf,fields)
  File "downloader/everythingLookup.py", line 271, in lookupKUPS
    song=track["SongName"])
  File "packages/libzarv.py", line 174, in getAlbumArtistNames
    mbArtists = mb.search_artists(query=artist,limit=10)['artist-list']
  File "/usr/local/lib/python3.4/dist-packages/musicbrainzngs/musicbrainz.py", line 846, in search_artists
    return _do_mb_search('artist', query, fields, limit, offset, strict)
  File "/usr/local/lib/python3.4/dist-packages/musicbrainzngs/musicbrainz.py", line 728, in _do_mb_search
    return _do_mb_query(entity, '', [], params)
  File "/usr/local/lib/python3.4/dist-packages/musicbrainzngs/musicbrainz.py", line 670, in _do_mb_query
    return _mb_request(path, 'GET', auth_required, args=args)
  File "/usr/local/lib/python3.4/dist-packages/musicbrainzngs/musicbrainz.py", line 374, in __call__
    return self.fun(*args, **kwargs)
  File "/usr/local/lib/python3.4/dist-packages/musicbrainzngs/musicbrainz.py", line 635, in _mb_request
    resp = _safe_read(opener, req, body)
  File "/usr/local/lib/python3.4/dist-packages/musicbrainzngs/musicbrainz.py", line 494, in _safe_read
    raise NetworkError("retried %i times" % max_retries, last_exc)
musicbrainzngs.musicbrainz.NetworkError: retried 8 times, caused by: timed out
Wed Jan 20 08:10:50 PST 2016
Traceback (most recent call last):
  File "downloader/everythingLookup.py", line 331, in <module>
    main()
  File "downloader/everythingLookup.py", line 326, in main
    lookupAll(sys.argv[1],conf,fields)
  File "downloader/everythingLookup.py", line 308, in lookupAll
    lookupKUPS(conf,fields)
  File "downloader/everythingLookup.py", line 271, in lookupKUPS
    song=track["SongName"])
  File "packages/libzarv.py", line 174, in getAlbumArtistNames
    mbArtists = mb.search_artists(query=artist,limit=10)['artist-list']
  File "/usr/local/lib/python3.4/dist-packages/musicbrainzngs/musicbrainz.py", line 846, in search_artists
    return _do_mb_search('artist', query, fields, limit, offset, strict)
  File "/usr/local/lib/python3.4/dist-packages/musicbrainzngs/musicbrainz.py", line 728, in _do_mb_search
    return _do_mb_query(entity, '', [], params)
  File "/usr/local/lib/python3.4/dist-packages/musicbrainzngs/musicbrainz.py", line 670, in _do_mb_query
    return _mb_request(path, 'GET', auth_required, args=args)
  File "/usr/local/lib/python3.4/dist-packages/musicbrainzngs/musicbrainz.py", line 374, in __call__
    return self.fun(*args, **kwargs)
  File "/usr/local/lib/python3.4/dist-packages/musicbrainzngs/musicbrainz.py", line 635, in _mb_request
    resp = _safe_read(opener, req, body)
  File "/usr/local/lib/python3.4/dist-packages/musicbrainzngs/musicbrainz.py", line 494, in _safe_read
    raise NetworkError("retried %i times" % max_retries, last_exc)
musicbrainzngs.musicbrainz.NetworkError: retried 8 times, caused by: HTTP Error 503: Service Unavailable
Wed Jan 20 08:12:43 PST 2016
Wed Jan 20 10:21:33 PST 2016
/usr/lib/python3/dist-packages/scipy/stats/distributions.py:1334: RuntimeWarning: invalid value encountered in double_scalars
  x = (x-loc)*1.0/scale
Error: cannot insert artist_genre into db
'neoclassical'
'neoclassical'
Error: cannot insert artist_genre into db
'fusion'
'fusion'
Error: cannot insert artist_genre into db
'mood'
'mood'
Error: cannot insert album_genre into db
'grunge'
'grunge'
HTTPConnectionPool(host='ws.audioscrobbler.com', port=80): Read timed out. (read timeout=9.05)
Error: cannot insert album_genre into db
'screamo'
'screamo'
Error: cannot insert artist_genre into db
'new.romantic'
'new.romantic'
Error: cannot insert album_genre into db
'beats'
'beats'
Error: cannot insert artist_genre into db
'stoner'
'stoner'
Error: cannot insert album_genre into db
'polka'
'polka'
Error: cannot insert artist_genre into db
'urban'
'urban'
Error: cannot insert album_genre into db
'ethereal'
'ethereal'
Error: cannot insert album_genre into db
'cosmic'
'cosmic'
Error: cannot insert album_genre into db
'electro.rock'
'electro.rock'
Error: cannot insert artist_genre into db
'chilout'
'chilout'
Traceback (most recent call last):
  File "/usr/local/lib/python3.4/dist-packages/musicbrainzngs/musicbrainz.py", line 454, in _safe_read
    f = opener.open(req)
  File "/usr/lib/python3.4/urllib/request.py", line 469, in open
    response = meth(req, response)
  File "/usr/lib/python3.4/urllib/request.py", line 579, in http_response
    'http', request, response, code, msg, hdrs)
  File "/usr/lib/python3.4/urllib/request.py", line 507, in error
    return self._call_chain(*args)
  File "/usr/lib/python3.4/urllib/request.py", line 441, in _call_chain
    result = func(*args)
  File "/usr/lib/python3.4/urllib/request.py", line 587, in http_error_default
    raise HTTPError(req.full_url, code, msg, hdrs, fp)
urllib.error.HTTPError: HTTP Error 400: Bad Request

During handling of the above exception, another exception occurred:

Traceback (most recent call last):
  File "downloader/everythingLookup.py", line 331, in <module>
    main()
  File "downloader/everythingLookup.py", line 326, in main
    lookupAll(sys.argv[1],conf,fields)
  File "downloader/everythingLookup.py", line 308, in lookupAll
    lookupKUPS(conf,fields)
  File "downloader/everythingLookup.py", line 271, in lookupKUPS
    song=track["SongName"])
  File "packages/libzarv.py", line 174, in getAlbumArtistNames
    mbArtists = mb.search_artists(query=artist,limit=10)['artist-list']
  File "/usr/local/lib/python3.4/dist-packages/musicbrainzngs/musicbrainz.py", line 846, in search_artists
    return _do_mb_search('artist', query, fields, limit, offset, strict)
  File "/usr/local/lib/python3.4/dist-packages/musicbrainzngs/musicbrainz.py", line 728, in _do_mb_search
    return _do_mb_query(entity, '', [], params)
  File "/usr/local/lib/python3.4/dist-packages/musicbrainzngs/musicbrainz.py", line 670, in _do_mb_query
    return _mb_request(path, 'GET', auth_required, args=args)
  File "/usr/local/lib/python3.4/dist-packages/musicbrainzngs/musicbrainz.py", line 374, in __call__
    return self.fun(*args, **kwargs)
  File "/usr/local/lib/python3.4/dist-packages/musicbrainzngs/musicbrainz.py", line 635, in _mb_request
    resp = _safe_read(opener, req, body)
  File "/usr/local/lib/python3.4/dist-packages/musicbrainzngs/musicbrainz.py", line 460, in _safe_read
    raise ResponseError(cause=exc)
musicbrainzngs.musicbrainz.ResponseError: caused by: HTTP Error 400: Bad Request
Wed Jan 20 13:54:46 PST 2016
Traceback (most recent call last):
  File "/usr/local/lib/python3.4/dist-packages/musicbrainzngs/musicbrainz.py", line 454, in _safe_read
    f = opener.open(req)
  File "/usr/lib/python3.4/urllib/request.py", line 469, in open
    response = meth(req, response)
  File "/usr/lib/python3.4/urllib/request.py", line 579, in http_response
    'http', request, response, code, msg, hdrs)
  File "/usr/lib/python3.4/urllib/request.py", line 507, in error
    return self._call_chain(*args)
  File "/usr/lib/python3.4/urllib/request.py", line 441, in _call_chain
    result = func(*args)
  File "/usr/lib/python3.4/urllib/request.py", line 587, in http_error_default
    raise HTTPError(req.full_url, code, msg, hdrs, fp)
urllib.error.HTTPError: HTTP Error 400: Bad Request

During handling of the above exception, another exception occurred:

Traceback (most recent call last):
  File "downloader/everythingLookup.py", line 331, in <module>
    main()
  File "downloader/everythingLookup.py", line 326, in main
    lookupAll(sys.argv[1],conf,fields)
  File "downloader/everythingLookup.py", line 308, in lookupAll
    lookupKUPS(conf,fields)
  File "downloader/everythingLookup.py", line 271, in lookupKUPS
    song=track["SongName"])
  File "packages/libzarv.py", line 174, in getAlbumArtistNames
    mbArtists = mb.search_artists(query=artist,limit=10)['artist-list']
  File "/usr/local/lib/python3.4/dist-packages/musicbrainzngs/musicbrainz.py", line 846, in search_artists
    return _do_mb_search('artist', query, fields, limit, offset, strict)
  File "/usr/local/lib/python3.4/dist-packages/musicbrainzngs/musicbrainz.py", line 728, in _do_mb_search
    return _do_mb_query(entity, '', [], params)
  File "/usr/local/lib/python3.4/dist-packages/musicbrainzngs/musicbrainz.py", line 670, in _do_mb_query
    return _mb_request(path, 'GET', auth_required, args=args)
  File "/usr/local/lib/python3.4/dist-packages/musicbrainzngs/musicbrainz.py", line 374, in __call__
    return self.fun(*args, **kwargs)
  File "/usr/local/lib/python3.4/dist-packages/musicbrainzngs/musicbrainz.py", line 635, in _mb_request
    resp = _safe_read(opener, req, body)
  File "/usr/local/lib/python3.4/dist-packages/musicbrainzngs/musicbrainz.py", line 460, in _safe_read
    raise ResponseError(cause=exc)
musicbrainzngs.musicbrainz.ResponseError: caused by: HTTP Error 400: Bad Request
Wed Jan 20 13:55:18 PST 2016
Traceback (most recent call last):
  File "/usr/local/lib/python3.4/dist-packages/musicbrainzngs/musicbrainz.py", line 454, in _safe_read
    f = opener.open(req)
  File "/usr/lib/python3.4/urllib/request.py", line 469, in open
    response = meth(req, response)
  File "/usr/lib/python3.4/urllib/request.py", line 579, in http_response
    'http', request, response, code, msg, hdrs)
  File "/usr/lib/python3.4/urllib/request.py", line 507, in error
    return self._call_chain(*args)
  File "/usr/lib/python3.4/urllib/request.py", line 441, in _call_chain
    result = func(*args)
  File "/usr/lib/python3.4/urllib/request.py", line 587, in http_error_default
    raise HTTPError(req.full_url, code, msg, hdrs, fp)
urllib.error.HTTPError: HTTP Error 400: Bad Request

During handling of the above exception, another exception occurred:

Traceback (most recent call last):
  File "downloader/everythingLookup.py", line 331, in <module>
    main()
  File "downloader/everythingLookup.py", line 326, in main
    lookupAll(sys.argv[1],conf,fields)
  File "downloader/everythingLookup.py", line 308, in lookupAll
    lookupKUPS(conf,fields)
  File "downloader/everythingLookup.py", line 271, in lookupKUPS
    song=track["SongName"])
  File "packages/libzarv.py", line 174, in getAlbumArtistNames
    mbArtists = mb.search_artists(query=artist,limit=10)['artist-list']
  File "/usr/local/lib/python3.4/dist-packages/musicbrainzngs/musicbrainz.py", line 846, in search_artists
    return _do_mb_search('artist', query, fields, limit, offset, strict)
  File "/usr/local/lib/python3.4/dist-packages/musicbrainzngs/musicbrainz.py", line 728, in _do_mb_search
    return _do_mb_query(entity, '', [], params)
  File "/usr/local/lib/python3.4/dist-packages/musicbrainzngs/musicbrainz.py", line 670, in _do_mb_query
    return _mb_request(path, 'GET', auth_required, args=args)
  File "/usr/local/lib/python3.4/dist-packages/musicbrainzngs/musicbrainz.py", line 374, in __call__
    return self.fun(*args, **kwargs)
  File "/usr/local/lib/python3.4/dist-packages/musicbrainzngs/musicbrainz.py", line 635, in _mb_request
    resp = _safe_read(opener, req, body)
  File "/usr/local/lib/python3.4/dist-packages/musicbrainzngs/musicbrainz.py", line 460, in _safe_read
    raise ResponseError(cause=exc)
musicbrainzngs.musicbrainz.ResponseError: caused by: HTTP Error 400: Bad Request
Wed Jan 20 13:55:49 PST 2016
Traceback (most recent call last):
  File "/usr/local/lib/python3.4/dist-packages/musicbrainzngs/musicbrainz.py", line 454, in _safe_read
    f = opener.open(req)
  File "/usr/lib/python3.4/urllib/request.py", line 469, in open
    response = meth(req, response)
  File "/usr/lib/python3.4/urllib/request.py", line 579, in http_response
    'http', request, response, code, msg, hdrs)
  File "/usr/lib/python3.4/urllib/request.py", line 507, in error
    return self._call_chain(*args)
  File "/usr/lib/python3.4/urllib/request.py", line 441, in _call_chain
    result = func(*args)
  File "/usr/lib/python3.4/urllib/request.py", line 587, in http_error_default
    raise HTTPError(req.full_url, code, msg, hdrs, fp)
urllib.error.HTTPError: HTTP Error 400: Bad Request

During handling of the above exception, another exception occurred:

Traceback (most recent call last):
  File "downloader/everythingLookup.py", line 331, in <module>
    main()
  File "downloader/everythingLookup.py", line 326, in main
    lookupAll(sys.argv[1],conf,fields)
  File "downloader/everythingLookup.py", line 308, in lookupAll
    lookupKUPS(conf,fields)
  File "downloader/everythingLookup.py", line 271, in lookupKUPS
    song=track["SongName"])
  File "packages/libzarv.py", line 174, in getAlbumArtistNames
    mbArtists = mb.search_artists(query=artist,limit=10)['artist-list']
  File "/usr/local/lib/python3.4/dist-packages/musicbrainzngs/musicbrainz.py", line 846, in search_artists
    return _do_mb_search('artist', query, fields, limit, offset, strict)
  File "/usr/local/lib/python3.4/dist-packages/musicbrainzngs/musicbrainz.py", line 728, in _do_mb_search
    return _do_mb_query(entity, '', [], params)
  File "/usr/local/lib/python3.4/dist-packages/musicbrainzngs/musicbrainz.py", line 670, in _do_mb_query
    return _mb_request(path, 'GET', auth_required, args=args)
  File "/usr/local/lib/python3.4/dist-packages/musicbrainzngs/musicbrainz.py", line 374, in __call__
    return self.fun(*args, **kwargs)
  File "/usr/local/lib/python3.4/dist-packages/musicbrainzngs/musicbrainz.py", line 635, in _mb_request
    resp = _safe_read(opener, req, body)
  File "/usr/local/lib/python3.4/dist-packages/musicbrainzngs/musicbrainz.py", line 460, in _safe_read
    raise ResponseError(cause=exc)
musicbrainzngs.musicbrainz.ResponseError: caused by: HTTP Error 400: Bad Request
Wed Jan 20 13:56:21 PST 2016
Traceback (most recent call last):
  File "/usr/local/lib/python3.4/dist-packages/musicbrainzngs/musicbrainz.py", line 454, in _safe_read
    f = opener.open(req)
  File "/usr/lib/python3.4/urllib/request.py", line 469, in open
    response = meth(req, response)
  File "/usr/lib/python3.4/urllib/request.py", line 579, in http_response
    'http', request, response, code, msg, hdrs)
  File "/usr/lib/python3.4/urllib/request.py", line 507, in error
    return self._call_chain(*args)
  File "/usr/lib/python3.4/urllib/request.py", line 441, in _call_chain
    result = func(*args)
  File "/usr/lib/python3.4/urllib/request.py", line 587, in http_error_default
    raise HTTPError(req.full_url, code, msg, hdrs, fp)
urllib.error.HTTPError: HTTP Error 400: Bad Request

During handling of the above exception, another exception occurred:

Traceback (most recent call last):
  File "downloader/everythingLookup.py", line 331, in <module>
    main()
  File "downloader/everythingLookup.py", line 326, in main
    lookupAll(sys.argv[1],conf,fields)
  File "downloader/everythingLookup.py", line 308, in lookupAll
    lookupKUPS(conf,fields)
  File "downloader/everythingLookup.py", line 271, in lookupKUPS
    song=track["SongName"])
  File "packages/libzarv.py", line 174, in getAlbumArtistNames
    mbArtists = mb.search_artists(query=artist,limit=10)['artist-list']
  File "/usr/local/lib/python3.4/dist-packages/musicbrainzngs/musicbrainz.py", line 846, in search_artists
    return _do_mb_search('artist', query, fields, limit, offset, strict)
  File "/usr/local/lib/python3.4/dist-packages/musicbrainzngs/musicbrainz.py", line 728, in _do_mb_search
    return _do_mb_query(entity, '', [], params)
  File "/usr/local/lib/python3.4/dist-packages/musicbrainzngs/musicbrainz.py", line 670, in _do_mb_query
    return _mb_request(path, 'GET', auth_required, args=args)
  File "/usr/local/lib/python3.4/dist-packages/musicbrainzngs/musicbrainz.py", line 374, in __call__
    return self.fun(*args, **kwargs)
  File "/usr/local/lib/python3.4/dist-packages/musicbrainzngs/musicbrainz.py", line 635, in _mb_request
    resp = _safe_read(opener, req, body)
  File "/usr/local/lib/python3.4/dist-packages/musicbrainzngs/musicbrainz.py", line 460, in _safe_read
    raise ResponseError(cause=exc)
musicbrainzngs.musicbrainz.ResponseError: caused by: HTTP Error 400: Bad Request
Wed Jan 20 13:56:53 PST 2016
Traceback (most recent call last):
  File "/usr/local/lib/python3.4/dist-packages/musicbrainzngs/musicbrainz.py", line 454, in _safe_read
    f = opener.open(req)
  File "/usr/lib/python3.4/urllib/request.py", line 469, in open
    response = meth(req, response)
  File "/usr/lib/python3.4/urllib/request.py", line 579, in http_response
    'http', request, response, code, msg, hdrs)
  File "/usr/lib/python3.4/urllib/request.py", line 507, in error
    return self._call_chain(*args)
  File "/usr/lib/python3.4/urllib/request.py", line 441, in _call_chain
    result = func(*args)
  File "/usr/lib/python3.4/urllib/request.py", line 587, in http_error_default
    raise HTTPError(req.full_url, code, msg, hdrs, fp)
urllib.error.HTTPError: HTTP Error 400: Bad Request

During handling of the above exception, another exception occurred:

Traceback (most recent call last):
  File "downloader/everythingLookup.py", line 331, in <module>
    main()
  File "downloader/everythingLookup.py", line 326, in main
    lookupAll(sys.argv[1],conf,fields)
  File "downloader/everythingLookup.py", line 308, in lookupAll
    lookupKUPS(conf,fields)
  File "downloader/everythingLookup.py", line 271, in lookupKUPS
    song=track["SongName"])
  File "packages/libzarv.py", line 174, in getAlbumArtistNames
    mbArtists = mb.search_artists(query=artist,limit=10)['artist-list']
  File "/usr/local/lib/python3.4/dist-packages/musicbrainzngs/musicbrainz.py", line 846, in search_artists
    return _do_mb_search('artist', query, fields, limit, offset, strict)
  File "/usr/local/lib/python3.4/dist-packages/musicbrainzngs/musicbrainz.py", line 728, in _do_mb_search
    return _do_mb_query(entity, '', [], params)
  File "/usr/local/lib/python3.4/dist-packages/musicbrainzngs/musicbrainz.py", line 670, in _do_mb_query
    return _mb_request(path, 'GET', auth_required, args=args)
  File "/usr/local/lib/python3.4/dist-packages/musicbrainzngs/musicbrainz.py", line 374, in __call__
    return self.fun(*args, **kwargs)
  File "/usr/local/lib/python3.4/dist-packages/musicbrainzngs/musicbrainz.py", line 635, in _mb_request
    resp = _safe_read(opener, req, body)
  File "/usr/local/lib/python3.4/dist-packages/musicbrainzngs/musicbrainz.py", line 460, in _safe_read
    raise ResponseError(cause=exc)
musicbrainzngs.musicbrainz.ResponseError: caused by: HTTP Error 400: Bad Request
Wed Jan 20 13:57:25 PST 2016
Traceback (most recent call last):
  File "/usr/local/lib/python3.4/dist-packages/musicbrainzngs/musicbrainz.py", line 454, in _safe_read
    f = opener.open(req)
  File "/usr/lib/python3.4/urllib/request.py", line 469, in open
    response = meth(req, response)
  File "/usr/lib/python3.4/urllib/request.py", line 579, in http_response
    'http', request, response, code, msg, hdrs)
  File "/usr/lib/python3.4/urllib/request.py", line 507, in error
    return self._call_chain(*args)
  File "/usr/lib/python3.4/urllib/request.py", line 441, in _call_chain
    result = func(*args)
  File "/usr/lib/python3.4/urllib/request.py", line 587, in http_error_default
    raise HTTPError(req.full_url, code, msg, hdrs, fp)
urllib.error.HTTPError: HTTP Error 400: Bad Request

During handling of the above exception, another exception occurred:

Traceback (most recent call last):
  File "downloader/everythingLookup.py", line 331, in <module>
    main()
  File "downloader/everythingLookup.py", line 326, in main
    lookupAll(sys.argv[1],conf,fields)
  File "downloader/everythingLookup.py", line 308, in lookupAll
    lookupKUPS(conf,fields)
  File "downloader/everythingLookup.py", line 271, in lookupKUPS
    song=track["SongName"])
  File "packages/libzarv.py", line 174, in getAlbumArtistNames
    mbArtists = mb.search_artists(query=artist,limit=10)['artist-list']
  File "/usr/local/lib/python3.4/dist-packages/musicbrainzngs/musicbrainz.py", line 846, in search_artists
    return _do_mb_search('artist', query, fields, limit, offset, strict)
  File "/usr/local/lib/python3.4/dist-packages/musicbrainzngs/musicbrainz.py", line 728, in _do_mb_search
    return _do_mb_query(entity, '', [], params)
  File "/usr/local/lib/python3.4/dist-packages/musicbrainzngs/musicbrainz.py", line 670, in _do_mb_query
    return _mb_request(path, 'GET', auth_required, args=args)
  File "/usr/local/lib/python3.4/dist-packages/musicbrainzngs/musicbrainz.py", line 374, in __call__
    return self.fun(*args, **kwargs)
  File "/usr/local/lib/python3.4/dist-packages/musicbrainzngs/musicbrainz.py", line 635, in _mb_request
    resp = _safe_read(opener, req, body)
  File "/usr/local/lib/python3.4/dist-packages/musicbrainzngs/musicbrainz.py", line 460, in _safe_read
    raise ResponseError(cause=exc)
musicbrainzngs.musicbrainz.ResponseError: caused by: HTTP Error 400: Bad Request
Wed Jan 20 13:57:56 PST 2016
Traceback (most recent call last):
  File "/usr/local/lib/python3.4/dist-packages/musicbrainzngs/musicbrainz.py", line 454, in _safe_read
    f = opener.open(req)
  File "/usr/lib/python3.4/urllib/request.py", line 469, in open
    response = meth(req, response)
  File "/usr/lib/python3.4/urllib/request.py", line 579, in http_response
    'http', request, response, code, msg, hdrs)
  File "/usr/lib/python3.4/urllib/request.py", line 507, in error
    return self._call_chain(*args)
  File "/usr/lib/python3.4/urllib/request.py", line 441, in _call_chain
    result = func(*args)
  File "/usr/lib/python3.4/urllib/request.py", line 587, in http_error_default
    raise HTTPError(req.full_url, code, msg, hdrs, fp)
urllib.error.HTTPError: HTTP Error 400: Bad Request

During handling of the above exception, another exception occurred:

Traceback (most recent call last):
  File "downloader/everythingLookup.py", line 331, in <module>
    main()
  File "downloader/everythingLookup.py", line 326, in main
    lookupAll(sys.argv[1],conf,fields)
  File "downloader/everythingLookup.py", line 308, in lookupAll
    lookupKUPS(conf,fields)
  File "downloader/everythingLookup.py", line 271, in lookupKUPS
    song=track["SongName"])
  File "packages/libzarv.py", line 174, in getAlbumArtistNames
    mbArtists = mb.search_artists(query=artist,limit=10)['artist-list']
  File "/usr/local/lib/python3.4/dist-packages/musicbrainzngs/musicbrainz.py", line 846, in search_artists
    return _do_mb_search('artist', query, fields, limit, offset, strict)
  File "/usr/local/lib/python3.4/dist-packages/musicbrainzngs/musicbrainz.py", line 728, in _do_mb_search
    return _do_mb_query(entity, '', [], params)
  File "/usr/local/lib/python3.4/dist-packages/musicbrainzngs/musicbrainz.py", line 670, in _do_mb_query
    return _mb_request(path, 'GET', auth_required, args=args)
  File "/usr/local/lib/python3.4/dist-packages/musicbrainzngs/musicbrainz.py", line 374, in __call__
    return self.fun(*args, **kwargs)
  File "/usr/local/lib/python3.4/dist-packages/musicbrainzngs/musicbrainz.py", line 635, in _mb_request
    resp = _safe_read(opener, req, body)
  File "/usr/local/lib/python3.4/dist-packages/musicbrainzngs/musicbrainz.py", line 460, in _safe_read
    raise ResponseError(cause=exc)
musicbrainzngs.musicbrainz.ResponseError: caused by: HTTP Error 400: Bad Request
Wed Jan 20 13:58:28 PST 2016
Traceback (most recent call last):
  File "/usr/local/lib/python3.4/dist-packages/musicbrainzngs/musicbrainz.py", line 454, in _safe_read
    f = opener.open(req)
  File "/usr/lib/python3.4/urllib/request.py", line 469, in open
    response = meth(req, response)
  File "/usr/lib/python3.4/urllib/request.py", line 579, in http_response
    'http', request, response, code, msg, hdrs)
  File "/usr/lib/python3.4/urllib/request.py", line 507, in error
    return self._call_chain(*args)
  File "/usr/lib/python3.4/urllib/request.py", line 441, in _call_chain
    result = func(*args)
  File "/usr/lib/python3.4/urllib/request.py", line 587, in http_error_default
    raise HTTPError(req.full_url, code, msg, hdrs, fp)
urllib.error.HTTPError: HTTP Error 400: Bad Request

During handling of the above exception, another exception occurred:

Traceback (most recent call last):
  File "downloader/everythingLookup.py", line 331, in <module>
    main()
  File "downloader/everythingLookup.py", line 326, in main
    lookupAll(sys.argv[1],conf,fields)
  File "downloader/everythingLookup.py", line 308, in lookupAll
    lookupKUPS(conf,fields)
  File "downloader/everythingLookup.py", line 271, in lookupKUPS
    song=track["SongName"])
  File "packages/libzarv.py", line 174, in getAlbumArtistNames
    mbArtists = mb.search_artists(query=artist,limit=10)['artist-list']
  File "/usr/local/lib/python3.4/dist-packages/musicbrainzngs/musicbrainz.py", line 846, in search_artists
    return _do_mb_search('artist', query, fields, limit, offset, strict)
  File "/usr/local/lib/python3.4/dist-packages/musicbrainzngs/musicbrainz.py", line 728, in _do_mb_search
    return _do_mb_query(entity, '', [], params)
  File "/usr/local/lib/python3.4/dist-packages/musicbrainzngs/musicbrainz.py", line 670, in _do_mb_query
    return _mb_request(path, 'GET', auth_required, args=args)
  File "/usr/local/lib/python3.4/dist-packages/musicbrainzngs/musicbrainz.py", line 374, in __call__
    return self.fun(*args, **kwargs)
  File "/usr/local/lib/python3.4/dist-packages/musicbrainzngs/musicbrainz.py", line 635, in _mb_request
    resp = _safe_read(opener, req, body)
  File "/usr/local/lib/python3.4/dist-packages/musicbrainzngs/musicbrainz.py", line 460, in _safe_read
    raise ResponseError(cause=exc)
musicbrainzngs.musicbrainz.ResponseError: caused by: HTTP Error 400: Bad Request
Wed Jan 20 13:59:00 PST 2016
Traceback (most recent call last):
  File "/usr/local/lib/python3.4/dist-packages/musicbrainzngs/musicbrainz.py", line 454, in _safe_read
    f = opener.open(req)
  File "/usr/lib/python3.4/urllib/request.py", line 469, in open
    response = meth(req, response)
  File "/usr/lib/python3.4/urllib/request.py", line 579, in http_response
    'http', request, response, code, msg, hdrs)
  File "/usr/lib/python3.4/urllib/request.py", line 507, in error
    return self._call_chain(*args)
  File "/usr/lib/python3.4/urllib/request.py", line 441, in _call_chain
    result = func(*args)
  File "/usr/lib/python3.4/urllib/request.py", line 587, in http_error_default
    raise HTTPError(req.full_url, code, msg, hdrs, fp)
urllib.error.HTTPError: HTTP Error 400: Bad Request

During handling of the above exception, another exception occurred:

Traceback (most recent call last):
  File "downloader/everythingLookup.py", line 331, in <module>
    main()
  File "downloader/everythingLookup.py", line 326, in main
    lookupAll(sys.argv[1],conf,fields)
  File "downloader/everythingLookup.py", line 308, in lookupAll
    lookupKUPS(conf,fields)
  File "downloader/everythingLookup.py", line 271, in lookupKUPS
    song=track["SongName"])
  File "packages/libzarv.py", line 174, in getAlbumArtistNames
    mbArtists = mb.search_artists(query=artist,limit=10)['artist-list']
  File "/usr/local/lib/python3.4/dist-packages/musicbrainzngs/musicbrainz.py", line 846, in search_artists
    return _do_mb_search('artist', query, fields, limit, offset, strict)
  File "/usr/local/lib/python3.4/dist-packages/musicbrainzngs/musicbrainz.py", line 728, in _do_mb_search
    return _do_mb_query(entity, '', [], params)
  File "/usr/local/lib/python3.4/dist-packages/musicbrainzngs/musicbrainz.py", line 670, in _do_mb_query
    return _mb_request(path, 'GET', auth_required, args=args)
  File "/usr/local/lib/python3.4/dist-packages/musicbrainzngs/musicbrainz.py", line 374, in __call__
    return self.fun(*args, **kwargs)
  File "/usr/local/lib/python3.4/dist-packages/musicbrainzngs/musicbrainz.py", line 635, in _mb_request
    resp = _safe_read(opener, req, body)
  File "/usr/local/lib/python3.4/dist-packages/musicbrainzngs/musicbrainz.py", line 460, in _safe_read
    raise ResponseError(cause=exc)
musicbrainzngs.musicbrainz.ResponseError: caused by: HTTP Error 400: Bad Request
Wed Jan 20 13:59:32 PST 2016
Len of artists is zero!!

/usr/lib/python3/dist-packages/scipy/stats/distributions.py:1334: RuntimeWarning: invalid value encountered in double_scalars
  x = (x-loc)*1.0/scale
Error: cannot insert artist_genre into db
'shoegaze'
'shoegaze'
Error: cannot insert artist_genre into db
'roots'
'roots'
Error: cannot insert artist_genre into db
'songwriter'
'songwriter'
Error: cannot insert artist_genre into db
'breakbeat'
'breakbeat'
Error: cannot insert artist_genre into db
'broken.beats'
'broken.beats'
Len of artists is zero!!

Error: cannot insert artist_genre into db
'mood'
'mood'
Error: cannot insert album_genre into db
'mood'
'mood'
Error: cannot insert artist_genre into db
'minimalism'
'minimalism'
Error: cannot insert artist_genre into db
'garage'
'garage'
Error: cannot insert artist_genre into db
'alternative'
'alternative'
Len of artists is zero!!

Len of artists is zero!!

Error: cannot insert artist_genre into db
'ragga'
'ragga'
Error: cannot insert artist_genre into db
'alternative.country'
'alternative.country'
Error: cannot insert artist_genre into db
'alternative.punk'
'alternative.punk'
Error: cannot insert artist_genre into db
'ragga'
'ragga'
Error: cannot insert artist_genre into db
'electro.house'
'electro.house'
Error: cannot insert artist_genre into db
'ragga'
'ragga'
Error: cannot insert artist_genre into db
'indie.dance'
'indie.dance'
Error: cannot insert artist_genre into db
'disco.house'
'disco.house'
Error: cannot insert album_genre into db
'britpop'
'britpop'
Error: cannot insert artist_genre into db
'alternative.punk'
'alternative.punk'
Error: cannot insert artist_genre into db
'electro.house'
'electro.house'
Error: cannot insert artist_genre into db
'rockabilly'
'rockabilly'
HTTPConnectionPool(host='ws.audioscrobbler.com', port=80): Read timed out. (read timeout=9.05)
Error: cannot insert album_genre into db
'exotica'
'exotica'
Error: cannot insert album_genre into db
'electronic'
'electronic'
Error: cannot insert artist_genre into db
'electronica'
'electronica'
Error: cannot insert album_genre into db
'stoner'
'stoner'
Error: cannot insert artist_genre into db
'rockabilly'
'rockabilly'
Error: cannot insert artist_genre into db
'electonic'
'electonic'
Error: cannot insert album_genre into db
'latin'
'latin'
Error: cannot insert artist_genre into db
'electonic'
'electonic'
Error: cannot insert artist_genre into db
'progressive'
'progressive'
Error: cannot insert artist_genre into db
'indie.dance'
'indie.dance'
Error: cannot insert artist_genre into db
'nu.soul'
'nu.soul'
Error: cannot insert artist_genre into db
'indie.dance'
'indie.dance'
Error: cannot insert artist_genre into db
'eclectic'
'eclectic'
Error: cannot insert album_genre into db
'nwobhm'
'nwobhm'
Error: cannot insert album_genre into db
'electronic'
'electronic'
Error: cannot insert artist_genre into db
'new.romantic'
'new.romantic'
Error: cannot insert artist_genre into db
'new.romantic'
'new.romantic'
Error: cannot insert artist_genre into db
'new.romantic'
'new.romantic'
Error: cannot insert artist_genre into db
'new.romantic'
'new.romantic'
HTTPConnectionPool(host='ws.audioscrobbler.com', port=80): Read timed out. (read timeout=9.05)
Error: cannot insert artist_genre into db
'new.romantic'
'new.romantic'
Error: cannot insert artist_genre into db
'new.romantic'
'new.romantic'
Error: cannot insert artist_genre into db
'new.romantic'
'new.romantic'
Error: cannot insert album_genre into db
'electronic'
'electronic'
Len of artists is zero!!

Len of artists is zero!!

Len of artists is zero!!

Len of artists is zero!!

Error: cannot insert album_genre into db
'electronic'
'electronic'
Error: cannot insert artist_genre into db
'neoclassical'
'neoclassical'
Error: cannot insert artist_genre into db
'drone'
'drone'
Error: cannot insert artist_genre into db
'drumandbass'
'drumandbass'
Error: cannot insert artist_genre into db
'duet'
'duet'
Error: cannot insert artist_genre into db
'drone'
'drone'
Error: cannot insert artist_genre into db
'glitch.hop'
'glitch.hop'
Error: cannot insert album_genre into db
'twee'
'twee'
Error: cannot insert artist_genre into db
'duet'
'duet'
Error: cannot insert album_genre into db
'space'
'space'
Error: cannot insert album_genre into db
'screamo'
'screamo'
Error: cannot insert album_genre into db
'screamo'
'screamo'
Error: cannot insert artist_genre into db
'numetal'
'numetal'
Error: cannot insert artist_genre into db
'numetal'
'numetal'
HTTPConnectionPool(host='ws.audioscrobbler.com', port=80): Read timed out. (read timeout=9.05)
Error: cannot insert artist_genre into db
'numetal'
'numetal'
Len of artists is zero!!

Len of artists is zero!!

Len of artists is zero!!

Error: cannot insert artist_genre into db
'alternative'
'alternative'
Error: cannot insert artist_genre into db
'trance'
'trance'
Len of artists is zero!!

Error: cannot insert album_genre into db
'swing'
'swing'
Error: cannot insert artist_genre into db
'flute'
'flute'
Error: cannot insert artist_genre into db
'flute'
'flute'
Error: cannot insert artist_genre into db
'flute'
'flute'
HTTPConnectionPool(host='ws.audioscrobbler.com', port=80): Read timed out. (read timeout=9.05)
Error: cannot insert artist_genre into db
'spiritual'
'spiritual'
Error: cannot insert artist_genre into db
'duet'
'duet'
Error: cannot insert artist_genre into db
'duet'
'duet'
Error: cannot insert artist_genre into db
'duet'
'duet'
HTTPConnectionPool(host='ws.audioscrobbler.com', port=80): Read timed out. (read timeout=9.05)
HTTPConnectionPool(host='ws.audioscrobbler.com', port=80): Read timed out. (read timeout=9.05)
HTTPConnectionPool(host='ws.audioscrobbler.com', port=80): Read timed out. (read timeout=9.05)
Error: cannot insert album_genre into db
'melancholic'
'melancholic'
Error: cannot insert album_genre into db
'psych'
'psych'
Error: cannot insert artist_genre into db
'modern.rock'
'modern.rock'
Error: cannot insert artist_genre into db
'modern.rock'
'modern.rock'
Error: cannot insert artist_genre into db
'drone'
'drone'
Error: cannot insert album_genre into db
'stoner'
'stoner'
Error: cannot insert artist_genre into db
'electronica'
'electronica'
Error: cannot insert artist_genre into db
'drone'
'drone'
Error: cannot insert artist_genre into db
'traditional.country'
'traditional.country'
Error: cannot insert artist_genre into db
'traditional.country'
'traditional.country'
Error: cannot insert artist_genre into db
'blues'
'blues'
Error: cannot insert artist_genre into db
'instrumentals'
'instrumentals'
Error: cannot insert artist_genre into db
'drumandbass'
'drumandbass'
Error: cannot insert artist_genre into db
'tropical'
'tropical'
Error: cannot insert artist_genre into db
'future.beats'
'future.beats'
Error: cannot insert artist_genre into db
'post.punk'
'post.punk'
Error: cannot insert album_genre into db
'cosmic'
'cosmic'
Len of artists is zero!!

Len of artists is zero!!

Len of artists is zero!!

Len of artists is zero!!

Len of artists is zero!!

Error: cannot insert artist_genre into db
'uk.house'
'uk.house'
Error: cannot insert artist_genre into db
'dream.pop'
'dream.pop'
Error: cannot insert artist_genre into db
'chilout'
'chilout'
Error: cannot insert artist_genre into db
'contemporary'
'contemporary'
Error: cannot insert artist_genre into db
'hiero'
'hiero'
Error: cannot insert artist_genre into db
'duet'
'duet'
Error: cannot associate artist Whispers with artist The Whispers in db
new row for relation "similar_artists" violates check constraint "artist_order"
  CODE: 23514
  LOCATION: File 'execMain.c', line 1659, in ExecConstraints from SERVER
  DETAIL: Failing row contains (13805, 13805, NaN).
RESULT:
  type: SingleXactCopy
  parameters: (13805, 13805, nan)
STATEMENT: [prepared]
  sql_parameter_types: ['INTEGER', 'INTEGER', 'DOUBLE PRECISION']
  statement_id: py:0x7f3384a43b70
  string:
    INSERT INTO similar_artists (artist1_id, artist2_id, similarity) VALUES ($1,$2,$3)
CONNECTION: [idle]
  client_address: 127.0.0.1/32
  client_port: 41381
  version:
    PostgreSQL 9.3.9 on x86_64-unknown-linux-gnu, compiled by gcc (Ubuntu 4.8.4-2ubuntu1~14.04) 4.8.4, 64-bit
CONNECTOR: [Host] pq://kups:***@localhost:5432/zarvox
  category: None
DRIVER: postgresql.driver.pq3.Driver
list index out of range
Error: cannot insert album_genre into db
'duet'
'duet'
Error: cannot insert artist_genre into db
'shibuya.kei'
'shibuya.kei'
Error: cannot insert artist_genre into db
'sample'
'sample'
Error: cannot insert artist_genre into db
'contemporary'
'contemporary'
Error: cannot insert album_genre into db
'electronic'
'electronic'
Error: cannot insert album_genre into db
'stoner'
'stoner'
Error: cannot insert artist_genre into db
'breakbeat'
'breakbeat'
Error: cannot insert artist_genre into db
'breakbeat'
'breakbeat'
HTTPConnectionPool(host='ws.audioscrobbler.com', port=80): Read timed out. (read timeout=9.05)
Error: cannot insert artist_genre into db
'duet'
'duet'
Error: cannot insert artist_genre into db
'electronic'
'electronic'
Error: cannot insert artist_genre into db
'acid.jazz'
'acid.jazz'
Error: cannot insert artist_genre into db
'electro.rock'
'electro.rock'
Error: cannot insert artist_genre into db
'alternative.country'
'alternative.country'
Error: cannot insert artist_genre into db
'flute'
'flute'
Error: cannot insert artist_genre into db
'grime'
'grime'
Error: cannot insert artist_genre into db
'grime'
'grime'
Error: cannot insert artist_genre into db
'elctronic'
'elctronic'
Error: cannot insert album_genre into db
'violin'
'violin'
Error: cannot insert artist_genre into db
'flute'
'flute'
Error: cannot insert artist_genre into db
'chamber.music'
'chamber.music'
Error: cannot insert artist_genre into db
'garage'
'garage'
Len of artists is zero!!

Error: cannot insert album_genre into db
'mood'
'mood'
Error: cannot insert artist_genre into db
'traditional.country'
'traditional.country'
Error: cannot insert artist_genre into db
'sample'
'sample'
Traceback (most recent call last):
  File "/usr/local/lib/python3.4/dist-packages/requests/packages/urllib3/connectionpool.py", line 376, in _make_request
    httplib_response = conn.getresponse(buffering=True)
TypeError: getresponse() got an unexpected keyword argument 'buffering'

During handling of the above exception, another exception occurred:

Traceback (most recent call last):
  File "downloader/everythingLookup.py", line 331, in <module>
    main()
  File "downloader/everythingLookup.py", line 326, in main
    lookupAll(sys.argv[1],conf,fields)
  File "downloader/everythingLookup.py", line 304, in lookupAll
    lookupGenre(conf,fields)
  File "downloader/everythingLookup.py", line 207, in lookupGenre
    for x in downloadGenreData(genre):
  File "downloader/everythingLookup.py", line 56, in downloadGenreData
    what = apihandle.request("browse",searchstr='',order_by='seeders',taglist=parse.quote(genre[0],'.'),page=(x),category='Music')
  File "/home/jon/projects/zarvox/packages/whatapi-0.1.2/whatapi/whatapi.py", line 106, in request
    timeout=(0.67,9.5))
  File "/usr/local/lib/python3.4/dist-packages/requests/sessions.py", line 480, in get
    return self.request('GET', url, **kwargs)
  File "/usr/local/lib/python3.4/dist-packages/requests/sessions.py", line 468, in request
    resp = self.send(prep, **send_kwargs)
  File "/usr/local/lib/python3.4/dist-packages/requests/sessions.py", line 576, in send
    r = adapter.send(request, **kwargs)
  File "/usr/local/lib/python3.4/dist-packages/requests/adapters.py", line 370, in send
    timeout=timeout
  File "/usr/local/lib/python3.4/dist-packages/requests/packages/urllib3/connectionpool.py", line 559, in urlopen
    body=body, headers=headers)
  File "/usr/local/lib/python3.4/dist-packages/requests/packages/urllib3/connectionpool.py", line 378, in _make_request
    httplib_response = conn.getresponse()
  File "/usr/lib/python3.4/http/client.py", line 1171, in getresponse
    response.begin()
  File "/usr/lib/python3.4/http/client.py", line 351, in begin
    version, status, reason = self._read_status()
  File "/usr/lib/python3.4/http/client.py", line 313, in _read_status
    line = str(self.fp.readline(_MAXLINE + 1), "iso-8859-1")
  File "/usr/lib/python3.4/socket.py", line 374, in readinto
    return self._sock.recv_into(b)
  File "/usr/lib/python3.4/ssl.py", line 769, in recv_into
    return self.read(nbytes, buffer)
  File "/usr/lib/python3.4/ssl.py", line 641, in read
    v = self._sslobj.read(len, buffer)
KeyboardInterrupt
